<mujoco model="lego_hand">
  <compiler angle="radian" meshdir="." autolimits="true" />

  <asset>
    <material name="black" rgba="0.2 0.2 0.2 1"/>
    <material name="gray"  rgba="0.5 0.5 0.5 1"/>

    <mesh name="palm1_part0"               file="palm1_part0.stl"/>
    <mesh name="palm1_part1"               file="palm1_part1.stl"/>
    <mesh name="finger_palm_servo_part0"   file="finger_palm_servo_part0.stl"/>
    <mesh name="finger_base_servo_part0"   file="finger_base_servo_part0.stl"/>
    <mesh name="finger_base_lever_part0"   file="finger_base_lever_part0.stl"/>
    <mesh name="finger_grammar1_part0"     file="finger_grammar1_part0.stl"/>
    <mesh name="finger_middle_servo_part0" file="finger_middle_servo_part0.stl"/>
    <mesh name="finger_middle_lever_part0" file="finger_middle_lever_part0.stl"/>
    <mesh name="finger_grammar2_part0"     file="finger_grammar2_part0.stl"/>
    <mesh name="finger_end_servo_part0"    file="finger_end_servo_part0.stl"/>
    <mesh name="finger_end_lever_part0"    file="finger_end_lever_part0.stl"/>
    <mesh name="finger_tip_part0"          file="finger_tip_part0.stl"/>
  </asset>

  <default>
    <geom contype="1" conaffinity="5" />
    <default class="servo">
      <position kp="0.5" kv="0.01" />
    </default>
  </default>

  <worldbody>

    <body name="hand_root" pos="0 0 0 " euler="3.14159 -0.43633 0">
    
      <geom type="mesh" mesh="palm1_part0" />
      <geom type="mesh" mesh="palm1_part1" />
      <geom type="mesh" mesh="finger_palm_servo_part0" />
      <geom pos="0.02508 0.024835 0" quat="0.961212 0 0 -0.275811" type="mesh"
        mesh="finger_palm_servo_part0" />
      <geom pos="0.041631 0.031106 0" quat="0.763777 0 0 -0.64548" type="mesh"
        mesh="finger_palm_servo_part0" />
      <geom pos="0.052468 0.010662 0" quat="0.578826 0 0 -0.815451" type="mesh"
        mesh="finger_palm_servo_part0" />
      <geom pos="0.059325 -0.005386 0" quat="0.240321 0 0 -0.970694" type="mesh"
        mesh="finger_palm_servo_part0" />
      <site name="grasp_site" pos="0.04 0.04 -0.02" group="4"/>
      <!-- Finger 1 -->
      <body name="f1_finger_base" pos="0.01863 0.06172 -0.028">
        <inertial pos="0 0 0" mass="0.01" diaginertia="1e-05 1e-05 1e-05" />
        <joint name="f1_finger_palm_joint" pos="0 0 0" axis="0 0 1" range="-0.698 0.698"
          actuatorfrcrange="-10 10" damping="0.1" frictionloss="0.01" />
        <geom pos="-0.01863 -0.06172 0.028" quat="1 0 0 0" type="mesh"
          mesh="finger_base_servo_part0" />
        <body name="f1_finger_base_lever" pos="0.01709 0.00043 -0.00464">
          <inertial pos="0 0 0" mass="0.025" diaginertia="2.5e-05 2.5e-05 2.5e-05" />
          <joint name="f1_finger_base_joint" pos="0 0 0" axis="-0.999419 -0.034078 0"
            range="0 1.5708" actuatorfrcrange="-10 10" damping="0.1" frictionloss="0.01" />
          <geom pos="-0.03572 -0.06215 0.03264" quat="1 0 0 0" type="mesh"
            mesh="finger_base_lever_part0" />
          <geom pos="-0.03572 -0.06215 0.03264" quat="1 0 0 0" type="mesh"
            mesh="finger_grammar1_part0" />
          <geom pos="-0.03572 -0.06215 0.03264" quat="1 0 0 0" type="mesh"
            mesh="finger_middle_servo_part0" />
          <body name="f1_finger_middle_lever" pos="-0.00115 0.03147 -0.00114">
            <inertial pos="0 0 0" mass="0.025" diaginertia="2.5e-05 2.5e-05 2.5e-05" />
            <joint name="f1_finger_middle_joint" pos="0 0 0" axis="-0.999419 -0.034078 0"
              range="0 1.5708" actuatorfrcrange="-10 10" damping="0.1" frictionloss="0.01" />
            <geom pos="-0.03457 -0.09362 0.03378" quat="1 0 0 0" type="mesh"
              mesh="finger_middle_lever_part0" />
            <geom pos="-0.03457 -0.09362 0.03378" quat="1 0 0 0" type="mesh"
              mesh="finger_grammar2_part0" />
            <geom pos="-0.03457 -0.09362 0.03378" quat="1 0 0 0" type="mesh"
              mesh="finger_end_servo_part0" />
            <body name="f1_finger_end_lever" pos="-0.00104 0.03148 -0.001">
              <inertial pos="0 0 0" mass="0.015" diaginertia="1.1e-05 1.1e-05 1.1e-05" />
              <joint name="f1_finger_end_joint" pos="0 0 0" axis="-0.999419 -0.034088 0"
                range="0 1.5708" actuatorfrcrange="-10 10" damping="0.1" frictionloss="0.01" />
              <geom pos="-0.03353 -0.1251 0.03478" quat="1 0 0 0" type="mesh"
                mesh="finger_end_lever_part0" />
              <geom pos="-0.03353 -0.1251 0.03478" quat="1 0 0 0" type="mesh"
                mesh="finger_tip_part0" />
              <site name="f1_tip" pos="0 0.035 0" group="4"/>
            </body>
          </body>
        </body>
      </body>
      <body name="f2_finger_base" pos="0.0736011 0.0672866 -0.028" quat="0.961212 0 0 -0.275811">
        <inertial pos="0 0 0" mass="0.01" diaginertia="1e-05 1e-05 1e-05" />
        <joint name="f2_finger_palm_joint" pos="0 0 0" axis="0 0 1" range="-0.698 0.698"
          actuatorfrcrange="-10 10" damping="0.1" frictionloss="0.01" />
        <geom pos="-0.01863 -0.06172 0.028" quat="1 0 0 0" type="mesh"
          mesh="finger_base_servo_part0" />
        <body name="f2_finger_base_lever" pos="0.01709 0.00043 -0.00464">
          <inertial pos="0 0 0" mass="0.025" diaginertia="2.5e-05 2.5e-05 2.5e-05" />
          <joint name="f2_finger_base_joint" pos="0 0 0" axis="-0.999419 -0.034078 0"
            range="0 1.5708" actuatorfrcrange="-10 10" damping="0.1" frictionloss="0.01" />
          <geom pos="-0.03572 -0.06215 0.03264" quat="1 0 0 0" type="mesh"
            mesh="finger_base_lever_part0" />
          <geom pos="-0.03572 -0.06215 0.03264" quat="1 0 0 0" type="mesh"
            mesh="finger_grammar1_part0" />
          <geom pos="-0.03572 -0.06215 0.03264" quat="1 0 0 0" type="mesh"
            mesh="finger_middle_servo_part0" />
          <body name="f2_finger_middle_lever" pos="-0.00115 0.03147 -0.00114">
            <inertial pos="0 0 0" mass="0.025" diaginertia="2.5e-05 2.5e-05 2.5e-05" />
            <joint name="f2_finger_middle_joint" pos="0 0 0" axis="-0.999419 -0.034078 0"
              range="0 1.5708" actuatorfrcrange="-10 10" damping="0.1" frictionloss="0.01" />
            <geom pos="-0.03457 -0.09362 0.03378" quat="1 0 0 0" type="mesh"
              mesh="finger_middle_lever_part0" />
            <geom pos="-0.03457 -0.09362 0.03378" quat="1 0 0 0" type="mesh"
              mesh="finger_grammar2_part0" />
            <geom pos="-0.03457 -0.09362 0.03378" quat="1 0 0 0" type="mesh"
              mesh="finger_end_servo_part0" />
            <body name="f2_finger_end_lever" pos="-0.00104 0.03148 -0.001">
              <inertial pos="0 0 0" mass="0.015" diaginertia="1.1e-05 1.1e-05 1.1e-05" />
              <joint name="f2_finger_end_joint" pos="0 0 0" axis="-0.999419 -0.034088 0"
                range="0 1.5708" actuatorfrcrange="-10 10" damping="0.1" frictionloss="0.01" />
              <geom pos="-0.03353 -0.1251 0.03478" quat="1 0 0 0" type="mesh"
                mesh="finger_end_lever_part0" />
              <geom pos="-0.03353 -0.1251 0.03478" quat="1 0 0 0" type="mesh"
                mesh="finger_tip_part0" />
              <site name="f2_tip" pos="0 0.035 0" group="4"/>
            </body>
          </body>
        </body>
      </body>
      <body name="f3_finger_base" pos="0.105593 0.0230261 -0.028" quat="0.763777 0 0 -0.64548">
        <inertial pos="0 0 0" mass="0.01" diaginertia="1e-05 1e-05 1e-05" />
        <joint name="f3_finger_palm_joint" pos="0 0 0" axis="0 0 1" range="-0.698 0.698"
          actuatorfrcrange="-10 10" damping="0.1" frictionloss="0.01" />
        <geom pos="-0.01863 -0.06172 0.028" quat="1 0 0 0" type="mesh"
          mesh="finger_base_servo_part0" />
        <body name="f3_finger_base_lever" pos="0.01709 0.00043 -0.00464">
          <inertial pos="0 0 0" mass="0.025" diaginertia="2.5e-05 2.5e-05 2.5e-05" />
          <joint name="f3_finger_base_joint" pos="0 0 0" axis="-0.999419 -0.034078 0"
            range="0 1.5708" actuatorfrcrange="-10 10" damping="0.1" frictionloss="0.01" />
          <geom pos="-0.03572 -0.06215 0.03264" quat="1 0 0 0" type="mesh"
            mesh="finger_base_lever_part0" />
          <geom pos="-0.03572 -0.06215 0.03264" quat="1 0 0 0" type="mesh"
            mesh="finger_grammar1_part0" />
          <geom pos="-0.03572 -0.06215 0.03264" quat="1 0 0 0" type="mesh"
            mesh="finger_middle_servo_part0" />
          <body name="f3_finger_middle_lever" pos="-0.00115 0.03147 -0.00114">
            <inertial pos="0 0 0" mass="0.025" diaginertia="2.5e-05 2.5e-05 2.5e-05" />
            <joint name="f3_finger_middle_joint" pos="0 0 0" axis="-0.999419 -0.034078 0"
              range="0 1.5708" actuatorfrcrange="-10 10" damping="0.1" frictionloss="0.01" />
            <geom pos="-0.03457 -0.09362 0.03378" quat="1 0 0 0" type="mesh"
              mesh="finger_middle_lever_part0" />
            <geom pos="-0.03457 -0.09362 0.03378" quat="1 0 0 0" type="mesh"
              mesh="finger_grammar2_part0" />
            <geom pos="-0.03457 -0.09362 0.03378" quat="1 0 0 0" type="mesh"
              mesh="finger_end_servo_part0" />
            <body name="f3_finger_end_lever" pos="-0.00104 0.03148 -0.001">
              <inertial pos="0 0 0" mass="0.015" diaginertia="1.1e-05 1.1e-05 1.1e-05" />
              <joint name="f3_finger_end_joint" pos="0 0 0" axis="-0.999419 -0.034088 0"
                range="0 1.5708" actuatorfrcrange="-10 10" damping="0.1" frictionloss="0.01" />
              <geom pos="-0.03353 -0.1251 0.03478" quat="1 0 0 0" type="mesh"
                mesh="finger_end_lever_part0" />
              <geom pos="-0.03353 -0.1251 0.03478" quat="1 0 0 0" type="mesh"
                mesh="finger_tip_part0" />
              <site name="f3_tip" pos="0 0.035 0" group="4"/>
            </body>
          </body>
        </body>
      </body>
      <body name="f4_finger_base" pos="0.104586 -0.0272876 -0.028" quat="0.578826 0 0 -0.815451">
        <inertial pos="0 0 0" mass="0.01" diaginertia="1e-05 1e-05 1e-05" />
        <joint name="f4_finger_palm_joint" pos="0 0 0" axis="0 0 1" range="-0.698 0.698"
          actuatorfrcrange="-10 10" damping="0.1" frictionloss="0.01" />
        <geom pos="-0.01863 -0.06172 0.028" quat="1 0 0 0" type="mesh"
          mesh="finger_base_servo_part0" />
        <body name="f4_finger_base_lever" pos="0.01709 0.00043 -0.00464">
          <inertial pos="0 0 0" mass="0.025" diaginertia="2.5e-05 2.5e-05 2.5e-05" />
          <joint name="f4_finger_base_joint" pos="0 0 0" axis="-0.999419 -0.034078 0"
            range="0 1.5708" actuatorfrcrange="-10 10" damping="0.1" frictionloss="0.01" />
          <geom pos="-0.03572 -0.06215 0.03264" quat="1 0 0 0" type="mesh"
            mesh="finger_base_lever_part0" />
          <geom pos="-0.03572 -0.06215 0.03264" quat="1 0 0 0" type="mesh"
            mesh="finger_grammar1_part0" />
          <geom pos="-0.03572 -0.06215 0.03264" quat="1 0 0 0" type="mesh"
            mesh="finger_middle_servo_part0" />
          <body name="f4_finger_middle_lever" pos="-0.00115 0.03147 -0.00114">
            <inertial pos="0 0 0" mass="0.025" diaginertia="2.5e-05 2.5e-05 2.5e-05" />
            <joint name="f4_finger_middle_joint" pos="0 0 0" axis="-0.999419 -0.034078 0"
              range="0 1.5708" actuatorfrcrange="-10 10" damping="0.1" frictionloss="0.01" />
            <geom pos="-0.03457 -0.09362 0.03378" quat="1 0 0 0" type="mesh"
              mesh="finger_middle_lever_part0" />
            <geom pos="-0.03457 -0.09362 0.03378" quat="1 0 0 0" type="mesh"
              mesh="finger_grammar2_part0" />
            <geom pos="-0.03457 -0.09362 0.03378" quat="1 0 0 0" type="mesh"
              mesh="finger_end_servo_part0" />
            <body name="f4_finger_end_lever" pos="-0.00104 0.03148 -0.001">
              <inertial pos="0 0 0" mass="0.015" diaginertia="1.1e-05 1.1e-05 1.1e-05" />
              <joint name="f4_finger_end_joint" pos="0 0 0" axis="-0.999419 -0.034088 0"
                range="0 1.5708" actuatorfrcrange="-10 10" damping="0.1" frictionloss="0.01" />
              <geom pos="-0.03353 -0.1251 0.03478" quat="1 0 0 0" type="mesh"
                mesh="finger_end_lever_part0" />
              <geom pos="-0.03353 -0.1251 0.03478" quat="1 0 0 0" type="mesh"
                mesh="finger_tip_part0" />
              <site name="f4_tip" pos="0 0.035 0" group="4"/>
            </body>
          </body>
        </body>
      </body>
      <body name="f5_finger_base" pos="0.0716427 -0.0686688 -0.028" quat="0.240321 0 0 -0.970694">
        <inertial pos="0 0 0" mass="0.01" diaginertia="1e-05 1e-05 1e-05" />
        <joint name="f5_finger_palm_joint" pos="0 0 0" axis="0 0 1" range="-0.698 0.698"
          actuatorfrcrange="-10 10" damping="0.1" frictionloss="0.01" />
        <geom pos="-0.01863 -0.06172 0.028" quat="1 0 0 0" type="mesh"
          mesh="finger_base_servo_part0" />
        <body name="f5_finger_base_lever" pos="0.01709 0.00043 -0.00464">
          <inertial pos="0 0 0" mass="0.025" diaginertia="2.5e-05 2.5e-05 2.5e-05" />
          <joint name="f5_finger_base_joint" pos="0 0 0" axis="-0.999419 -0.034078 0"
            range="0 1.5708" actuatorfrcrange="-10 10" damping="0.1" frictionloss="0.01" />
          <geom pos="-0.03572 -0.06215 0.03264" quat="1 0 0 0" type="mesh"
            mesh="finger_base_lever_part0" />
          <geom pos="-0.03572 -0.06215 0.03264" quat="1 0 0 0" type="mesh"
            mesh="finger_grammar1_part0" />
          <geom pos="-0.03572 -0.06215 0.03264" quat="1 0 0 0" type="mesh"
            mesh="finger_middle_servo_part0" />
          <body name="f5_finger_middle_lever" pos="-0.00115 0.03147 -0.00114">
            <inertial pos="0 0 0" mass="0.025" diaginertia="2.5e-05 2.5e-05 2.5e-05" />
            <joint name="f5_finger_middle_joint" pos="0 0 0" axis="-0.999419 -0.034078 0"
              range="0 1.5708" actuatorfrcrange="-10 10" damping="0.1" frictionloss="0.01" />
            <geom pos="-0.03457 -0.09362 0.03378" quat="1 0 0 0" type="mesh"
              mesh="finger_middle_lever_part0" />
            <geom pos="-0.03457 -0.09362 0.03378" quat="1 0 0 0" type="mesh"
              mesh="finger_grammar2_part0" />
            <geom pos="-0.03457 -0.09362 0.03378" quat="1 0 0 0" type="mesh"
              mesh="finger_end_servo_part0" />
            <body name="f5_finger_end_lever" pos="-0.00104 0.03148 -0.001">
              <inertial pos="0 0 0" mass="0.015" diaginertia="1.1e-05 1.1e-05 1.1e-05" />
              <joint name="f5_finger_end_joint" pos="0 0 0" axis="-0.999419 -0.034088 0"
                range="0 1.5708" actuatorfrcrange="-10 10" damping="0.1" frictionloss="0.01" />
              <geom pos="-0.03353 -0.1251 0.03478" quat="1 0 0 0" type="mesh"
                mesh="finger_end_lever_part0" />
              <geom pos="-0.03353 -0.1251 0.03478" quat="1 0 0 0" type="mesh"
                mesh="finger_tip_part0" />
              <site name="f5_tip" pos="0 0.035 0" group="4"/>
            </body>
          </body>
        </body>
      </body>
    </body>
  </worldbody>

  <actuator>
    <position name="f1_finger_palm_joint" class="servo" joint="f1_finger_palm_joint"
      forcerange="-0.8 0.8" inheritrange="1" />
    <position name="f1_finger_base_joint" class="servo" joint="f1_finger_base_joint"
      forcerange="-0.8 0.8" inheritrange="1" />
    <position name="f1_finger_middle_joint" class="servo" joint="f1_finger_middle_joint"
      forcerange="-0.8 0.8" inheritrange="1" />
    <position name="f1_finger_end_joint" class="servo" joint="f1_finger_end_joint"
      forcerange="-0.3 0.3" inheritrange="1" />
    <position name="f2_finger_palm_joint" class="servo" joint="f2_finger_palm_joint"
      forcerange="-0.8 0.8" inheritrange="1" />
    <position name="f2_finger_base_joint" class="servo" joint="f2_finger_base_joint"
      forcerange="-0.8 0.8" inheritrange="1" />
    <position name="f2_finger_middle_joint" class="servo" joint="f2_finger_middle_joint"
      forcerange="-0.8 0.8" inheritrange="1" />
    <position name="f2_finger_end_joint" class="servo" joint="f2_finger_end_joint"
      forcerange="-0.3 0.3" inheritrange="1" />
    <position name="f3_finger_palm_joint" class="servo" joint="f3_finger_palm_joint"
      forcerange="-0.8 0.8" inheritrange="1" />
    <position name="f3_finger_base_joint" class="servo" joint="f3_finger_base_joint"
      forcerange="-0.8 0.8" inheritrange="1" />
    <position name="f3_finger_middle_joint" class="servo" joint="f3_finger_middle_joint"
      forcerange="-0.8 0.8" inheritrange="1" />
    <position name="f3_finger_end_joint" class="servo" joint="f3_finger_end_joint"
      forcerange="-0.3 0.3" inheritrange="1" />
    <position name="f4_finger_palm_joint" class="servo" joint="f4_finger_palm_joint"
      forcerange="-0.8 0.8" inheritrange="1" />
    <position name="f4_finger_base_joint" class="servo" joint="f4_finger_base_joint"
      forcerange="-0.8 0.8" inheritrange="1" />
    <position name="f4_finger_middle_joint" class="servo" joint="f4_finger_middle_joint"
      forcerange="-0.8 0.8" inheritrange="1" />
    <position name="f4_finger_end_joint" class="servo" joint="f4_finger_end_joint"
      forcerange="-0.3 0.3" inheritrange="1" />
    <position name="f5_finger_palm_joint" class="servo" joint="f5_finger_palm_joint"
      forcerange="-0.8 0.8" inheritrange="1" />
    <position name="f5_finger_base_joint" class="servo" joint="f5_finger_base_joint"
      forcerange="-0.8 0.8" inheritrange="1" />
    <position name="f5_finger_middle_joint" class="servo" joint="f5_finger_middle_joint"
      forcerange="-0.8 0.8" inheritrange="1" />
    <position name="f5_finger_end_joint" class="servo" joint="f5_finger_end_joint"
      forcerange="-0.3 0.3" inheritrange="1" />
  </actuator>
</mujoco>
